<?xml version="1.0"?>
<robot name="my_robot">
<link name="base_link">
    <visual>
      <geometry><box size="0.5 0.3 0.1"/></geometry>
      <material name="blue"><color rgba="0 0 0.8 1"/></material>
    </visual>
    
    <collision>
      <geometry><box size="0.5 0.3 0.1"/></geometry>
    </collision>
    <inertial>
     <origin xyz="0 0 0" rpy="0 0 0"/>
     <mass value="5.0"/>
     <inertia ixx="0.0416" ixy="0" ixz="0" iyy="0.1083" iyz="0" izz="0.1416"/>
     </inertial>
  </link>

  <link name="wheel_left">
    <visual>
      <geometry><cylinder length="0.05" radius="0.1"/></geometry>
      <material name="black"><color rgba="0 0 0 1"/></material>
    </visual>
    
    <collision>
     <geometry><cylinder length="0.05" radius="0.1"/></geometry>
    </collision>
    
    <inertial>
      <origin xyz="0 0 0" rpy="0 0 0"/>
      <mass value="0.5"/>
      <inertia ixx="0.00135" ixy="0" ixz="0" iyy="0.00135" iyz="0" izz="0.0025"/>
    </inertial>
  </link>
  
  <link name="wheel_right">
    <visual>
      <geometry><cylinder length="0.05" radius="0.1"/></geometry>
      <material name="red"><color rgba="0 0 0 1"/></material>
    </visual>
    
    <collision>
     <geometry><cylinder length="0.05" radius="0.1"/></geometry>
    </collision>
    
    <inertial>
      <origin xyz="0 0 0" rpy="0 0 0"/>
      <mass value="0.5"/>
      <inertia ixx="0.00135" ixy="0" ixz="0" iyy="0.00135" iyz="0" izz="0.0025"/>
    </inertial>
  </link>

  <joint name="base_to_wheel" type="continuous">
    <parent link="base_link"/>
    <child link="wheel_left"/>
    <origin xyz="0 0.2 0" rpy="1.5708 0 0"/> <axis xyz="0 0 1"/> </joint>
    
  <joint name="base_to_wheel_right" type="continuous">
    <parent link="base_link"/>
    <child link="wheel_right"/>
    <origin xyz="0 -0.2 0" rpy="-1.5708 0 0"/> <axis xyz="0 0 1"/> </joint>
    
  <link name="caster_wheel">
    <visual>
      <geometry><sphere radius="0.05"/></geometry>
      <material name="grey"><color rgba="0.5 0.5 0.5 1"/></material>
    </visual>
    
    <collision>
      <geometry><sphere radius="0.05"/></geometry>
    </collision>
    
    <inertial>
      <mass value="0.1"/>
      <inertia ixx="0.0001" ixy="0" ixz="0" iyy="0.0001" iyz="0" izz="0.0001"/>
    </inertial>
  </link>

  <joint name="caster_wheel_joint" type="fixed">
    <parent link="base_link"/>
    <child link="caster_wheel"/>
    <origin xyz="0.2 0 -0.05" rpy="0 0 0"/>
  </joint>
  
  <gazebo>
    <plugin name="diff_drive" filename="libgazebo_ros_diff_drive.so">
      <left_joint>base_to_wheel</left_joint>
      <right_joint>base_to_wheel_right</right_joint>
      <wheel_separation>0.4</wheel_separation>
      <wheel_diameter>0.2</wheel_diameter>
      <ros>
        <remapping>cmd_vel:=cmd_vel</remapping>
      </ros>
    </plugin>
  </gazebo>
    
</robot>
